Workbook

Sheet REGISTRO DIARIO
A1: REGISTRO DIÁRIO DE PROSPECÇÃO — 2026
A2: DATA | B2: DIA | C2: PROSP. ENVIADAS | D2: RESPOSTAS | E2: REUNIÕES AGENDADAS (nº) | F2: REUNIÕES REALIZADAS (nº) | G2: FECHAMENTOS (nº) | H2: LEADS → COMUNIDADE (nº) | I2: OBSERVAÇÕES
A3: ── JAN ──
A4: 46023 | B4: Qui
A5: 46024 | B5: Sex
A6: 46027 | B6: Seg
A7: 46028 | B7: Ter
A8: 46029 | B8: Qua
A9: Semana 1
A10: 46030 | B10: Qui
A11: 46031 | B11: Sex
A12: 46034 | B12: Seg
A13: 46035 | B13: Ter
A14: 46036 | B14: Qua
A15: Semana 2
A16: 46037 | B16: Qui
A17: 46038 | B17: Sex
A18: 46041 | B18: Seg
A19: 46042 | B19: Ter
A20: 46043 | B20: Qua
A21: Semana 3
A22: 46044 | B22: Qui
A23: 46045 | B23: Sex
A24: 46048 | B24: Seg
A25: 46049 | B25: Ter
A26: 46050 | B26: Qua
A27: Semana 4
A28: 46051 | B28: Qui
A29: 46052 | B29: Sex
A30: ── FEV ──
A31: 46055 | B31: Seg
A32: 46056 | B32: Ter
A33: 46057 | B33: Qua
A34: 46058 | B34: Qui
A35: 46059 | B35: Sex
A36: Semana 1
A37: 46062 | B37: Seg
A38: 46063 | B38: Ter
A39: 46064 | B39: Qua
A40: 46065 | B40: Qui
...

Sheet SEMANAL
A1: PROSPECÇÃO SEMANAL — preencha toda sexta-feira
A2: Mês de referência: 01/07/2026 | B2: =DATE(2026,7,1) -> 46204
A3: INDICADOR | B3: SEM 1 | C3: SEM 2 | D3: SEM 3 | E3: SEM 4 | F3: SEM 5 | G3: TOTAL MÊS | H3: STATUS
A4: Metas de referência | B4: 150 | C4: 150 | D4: 150 | E4: 150 | F4: 150 | G4: Meta: 600/mês
A5: Prospecções enviadas | Meta: 150/sem | B5: =SUMIFS('REGISTRO DIARIO'!C:C,'REGISTRO DIARIO'!A:A,">="&$B$2,'REGISTRO DIARIO'!A:A,"<="&($B$2+6)) -> 0 | C5: =SUMIFS('REGISTRO DIARIO'!C:C,'REGISTRO DIARIO'!A:A,">="&($B$2+7),'REGISTRO DIARIO'!A:A,"<="&($B$2+13)) -> 0 | D5: =SUMIFS('REGISTRO DIARIO'!C:C,'REGISTRO DIARIO'!A:A,">="&($B$2+14),'REGISTRO DIARIO'!A:A,"<="&($B$2+20)) -> 0 | E5: =SUMIFS('REGISTRO DIARIO'!C:C,'REGISTRO DIARIO'!A:A,">="&($B$2+21),'REGISTRO DIARIO'!A:A,"<="&($B$2+27)) -> 123 | F5: =SUMIFS('REGISTRO DIARIO'!C:C,'REGISTRO DIARIO'!A:A,">="&($B$2+28),'REGISTRO DIARIO'!A:A,"<="&($B$2+34)) -> 0 | G5: =SUM(B5:F5) -> 123 | H5: =IF(B5=0,"—",IF(B5>=150,"VERDE",IF(B5>=100,"AMARELO","VERMELHO"))) -> —
A6: Respostas recebidas | Meta: 8-10/sem | B6: =SUMIFS('REGISTRO DIARIO'!D:D,'REGISTRO DIARIO'!A:A,">="&$B$2,'REGISTRO DIARIO'!A:A,"<="&($B$2+6)) -> 0 | C6: =SUMIFS('REGISTRO DIARIO'!D:D,'REGISTRO DIARIO'!A:A,">="&($B$2+7),'REGISTRO DIARIO'!A:A,"<="&($B$2+13)) -> 0 | D6: =SUMIFS('REGISTRO DIARIO'!D:D,'REGISTRO DIARIO'!A:A,">="&($B$2+14),'REGISTRO DIARIO'!A:A,"<="&($B$2+20)) -> 0 | E6: =SUMIFS('REGISTRO DIARIO'!D:D,'REGISTRO DIARIO'!A:A,">="&($B$2+21),'REGISTRO DIARIO'!A:A,"<="&($B$2+27)) -> 87 | F6: =SUMIFS('REGISTRO DIARIO'!D:D,'REGISTRO DIARIO'!A:A,">="&($B$2+28),'REGISTRO DIARIO'!A:A,"<="&($B$2+34)) -> 0 | G6: =SUM(B6:F6) -> 87
A7: Taxa de resposta (%) | Meta: ≥5% | B7: =IFERROR(B6/B5,"") | C7: =IFERROR(C6/C5,"") | D7: =IFERROR(D6/D5,"") | E7: =IFERROR(E6/E5,"") -> 0.70731707 | F7: =IFERROR(F6/F5,"") | G7: =IFERROR(G6/G5,"") -> 0.70731707
A8: Reuniões agendadas | Meta: 5-8/sem | B8: =SUMIFS('REGISTRO DIARIO'!E:E,'REGISTRO DIARIO'!A:A,">="&$B$2,'REGISTRO DIARIO'!A:A,"<="&($B$2+6)) -> 0 | C8: =SUMIFS('REGISTRO DIARIO'!E:E,'REGISTRO DIARIO'!A:A,">="&($B$2+7),'REGISTRO DIARIO'!A:A,"<="&($B$2+13)) -> 0 | D8: =SUMIFS('REGISTRO DIARIO'!E:E,'REGISTRO DIARIO'!A:A,">="&($B$2+14),'REGISTRO DIARIO'!A:A,"<="&($B$2+20)) -> 0 | E8: =SUMIFS('REGISTRO DIARIO'!E:E,'REGISTRO DIARIO'!A:A,">="&($B$2+21),'REGISTRO DIARIO'!A:A,"<="&($B$2+27)) -> 54 | F8: =SUMIFS('REGISTRO DIARIO'!E:E,'REGISTRO DIARIO'!A:A,">="&($B$2+28),'REGISTRO DIARIO'!A:A,"<="&($B$2+34)) -> 0 | G8: =SUM(B8:F8) -> 54
A9: Taxa de agendamento (%) | Meta: ≥5% | B9: =IFERROR(B8/B5,"") | C9: =IFERROR(C8/C5,"") | D9: =IFERROR(D8/D5,"") | E9: =IFERROR(E8/E5,"") -> 0.43902439 | F9: =IFERROR(F8/F5,"") | G9: =IFERROR(G8/G5,"") -> 0.43902439
A10: Reuniões realizadas | Meta: ≥80% agendado | B10: =SUMIFS('REGISTRO DIARIO'!F:F,'REGISTRO DIARIO'!A:A,">="&$B$2,'REGISTRO DIARIO'!A:A,"<="&($B$2+6)) -> 0 | C10: =SUMIFS('REGISTRO DIARIO'!F:F,'REGISTRO DIARIO'!A:A,">="&($B$2+7),'REGISTRO DIARIO'!A:A,"<="&($B$2+13)) -> 0 | D10: =SUMIFS('REGISTRO DIARIO'!F:F,'REGISTRO DIARIO'!A:A,">="&($B$2+14),'REGISTRO DIARIO'!A:A,"<="&($B$2+20)) -> 0 | E10: =SUMIFS('REGISTRO DIARIO'!F:F,'REGISTRO DIARIO'!A:A,">="&($B$2+21),'REGISTRO DIARIO'!A:A,"<="&($B$2+27)) -> 38 | F10: =SUMIFS('REGISTRO DIARIO'!F:F,'REGISTRO DIARIO'!A:A,">="&($B$2+28),'REGISTRO DIARIO'!A:A,"<="&($B$2+34)) -> 0 | G10: =SUM(B10:F10) -> 38
A11: Taxa de realização (%) | Meta: ≥80% | B11: =IFERROR(B10/B8,"") | C11: =IFERROR(C10/C8,"") | D11: =IFERROR(D10/D8,"") | E11: =IFERROR(E10/E8,"") -> 0.7037037 | F11: =IFERROR(F10/F8,"") | G11: =IFERROR(G10/G8,"") -> 0.7037037
A12: Planos de ação fechados | Meta: 1/sem | B12: =SUMIFS('REGISTRO DIARIO'!G:G,'REGISTRO DIARIO'!A:A,">="&$B$2,'REGISTRO DIARIO'!A:A,"<="&($B$2+6)) -> 0 | C12: =SUMIFS('REGISTRO DIARIO'!G:G,'REGISTRO DIARIO'!A:A,">="&($B$2+7),'REGISTRO DIARIO'!A:A,"<="&($B$2+13)) -> 0 | D12: =SUMIFS('REGISTRO DIARIO'!G:G,'REGISTRO DIARIO'!A:A,">="&($B$2+14),'REGISTRO DIARIO'!A:A,"<="&($B$2+20)) -> 0 | E12: =SUMIFS('REGISTRO DIARIO'!G:G,'REGISTRO DIARIO'!A:A,">="&($B$2+21),'REGISTRO DIARIO'!A:A,"<="&($B$2+27)) -> 2 | F12: =SUMIFS('REGISTRO DIARIO'!G:G,'REGISTRO DIARIO'!A:A,">="&($B$2+28),'REGISTRO DIARIO'!A:A,"<="&($B$2+34)) -> 0 | G12: =SUM(B12:F12) -> 2
A13: Taxa de fechamento (%) | Meta: ≥11% | B13: =IFERROR(B12/B10,"") | C13: =IFERROR(C12/C10,"") | D13: =IFERROR(D12/D10,"") | E13: =IFERROR(E12/E10,"") -> 0.052631579 | F13: =IFERROR(F12/F10,"") | G13: =IFERROR(G12/G10,"") -> 0.052631579
A14: Leads convidados p/ comunidade | B14: =SUMIFS('REGISTRO DIARIO'!H:H,'REGISTRO DIARIO'!A:A,">="&$B$2,'REGISTRO DIARIO'!A:A,"<="&($B$2+6)) -> 0 | C14: =SUMIFS('REGISTRO DIARIO'!H:H,'REGISTRO DIARIO'!A:A,">="&($B$2+7),'REGISTRO DIARIO'!A:A,"<="&($B$2+13)) -> 0 | D14: =SUMIFS('REGISTRO DIARIO'!H:H,'REGISTRO DIARIO'!A:A,">="&($B$2+14),'REGISTRO DIARIO'!A:A,"<="&($B$2+20)) -> 0 | E14: =SUMIFS('REGISTRO DIARIO'!H:H,'REGISTRO DIARIO'!A:A,">="&($B$2+21),'REGISTRO DIARIO'!A:A,"<="&($B$2+27)) -> 12 | F14: =SUMIFS('REGISTRO DIARIO'!H:H,'REGISTRO DIARIO'!A:A,">="&($B$2+28),'REGISTRO DIARIO'!A:A,"<="&($B$2+34)) -> 0 | G14: =SUM(B14:F14) -> 12

Sheet MENSAL
A1: RESULTADOS MENSAIS — Janeiro a Dezembro | B1: JAN | C1: FEV | D1: MAR | E1: ABR | F1: MAI | G1: JUN | H1: JUL | I1: AGO | J1: SET | K1: OUT | L1: NOV | M1: DEZ | N1: META
A3: INDICADOR | B3: JAN | C3: FEV | D3: MAR | E3: ABR | F3: MAI | G3: JUN | H3: JUL | I3: AGO | J3: SET | K3: OUT | L3: NOV | M3: DEZ | N3: META
A4: ── PROSPECÇÃO ──
A5: Total de prospecções | B5: =SUMIFS('REGISTRO DIARIO'!C:C,'REGISTRO DIARIO'!A:A,">="&DATE(2026,1,1),'REGISTRO DIARIO'!A:A,"<"&DATE(2026,2,1)) -> 0 | C5: =SUMIFS('REGISTRO DIARIO'!C:C,'REGISTRO DIARIO'!A:A,">="&DATE(2026,2,1),'REGISTRO DIARIO'!A:A,"<"&DATE(2026,3,1)) -> 0 | D5: =SUMIFS('REGISTRO DIARIO'!C:C,'REGISTRO DIARIO'!A:A,">="&DATE(2026,3,1),'REGISTRO DIARIO'!A:A,"<"&DATE(2026,4,1)) -> 0 | E5: =SUMIFS('REGISTRO DIARIO'!C:C,'REGISTRO DIARIO'!A:A,">="&DATE(2026,4,1),'REGISTRO DIARIO'!A:A,"<"&DATE(2026,5,1)) -> 0 | F5: =SUMIFS('REGISTRO DIARIO'!C:C,'REGISTRO DIARIO'!A:A,">="&DATE(2026,5,1),'REGISTRO DIARIO'!A:A,"<"&DATE(2026,6,1)) -> 0 | G5: =SUMIFS('REGISTRO DIARIO'!C:C,'REGISTRO DIARIO'!A:A,">="&DATE(2026,6,1),'REGISTRO DIARIO'!A:A,"<"&DATE(2026,7,1)) -> 0 | H5: =SUMIFS('REGISTRO DIARIO'!C:C,'REGISTRO DIARIO'!A:A,">="&DATE(2026,7,1),'REGISTRO DIARIO'!A:A,"<"&DATE(2026,8,1)) -> 123 | I5: =SUMIFS('REGISTRO DIARIO'!C:C,'REGISTRO DIARIO'!A:A,">="&DATE(2026,8,1),'REGISTRO DIARIO'!A:A,"<"&DATE(2026,9,1)) -> 0 | J5: =SUMIFS('REGISTRO DIARIO'!C:C,'REGISTRO DIARIO'!A:A,">="&DATE(2026,9,1),'REGISTRO DIARIO'!A:A,"<"&DATE(2026,10,1)) -> 0 | K5: =SUMIFS('REGISTRO DIARIO'!C:C,'REGISTRO DIARIO'!A:A,">="&DATE(2026,10,1),'REGISTRO DIARIO'!A:A,"<"&DATE(2026,11,1)) -> 0 | L5: =SUMIFS('REGISTRO DIARIO'!C:C,'REGISTRO DIARIO'!A:A,">="&DATE(2026,11,1),'REGISTRO DIARIO'!A:A,"<"&DATE(2026,12,1)) -> 0 | M5: =SUMIFS('REGISTRO DIARIO'!C:C,'REGISTRO DIARIO'!A:A,">="&DATE(2026,12,1),'REGISTRO DIARIO'!A:A,"<"&DATE(2027,1,1)) -> 0 | N5: Meta: 600/mês
A6: Reuniões realizadas | B6: =SUMIFS('REGISTRO DIARIO'!F:F,'REGISTRO DIARIO'!A:A,">="&DATE(2026,1,1),'REGISTRO DIARIO'!A:A,"<"&DATE(2026,2,1)) -> 0 | C6: =SUMIFS('REGISTRO DIARIO'!F:F,'REGISTRO DIARIO'!A:A,">="&DATE(2026,2,1),'REGISTRO DIARIO'!A:A,"<"&DATE(2026,3,1)) -> 0 | D6: =SUMIFS('REGISTRO DIARIO'!F:F,'REGISTRO DIARIO'!A:A,">="&DATE(2026,3,1),'REGISTRO DIARIO'!A:A,"<"&DATE(2026,4,1)) -> 0 | E6: =SUMIFS('REGISTRO DIARIO'!F:F,'REGISTRO DIARIO'!A:A,">="&DATE(2026,4,1),'REGISTRO DIARIO'!A:A,"<"&DATE(2026,5,1)) -> 0 | F6: =SUMIFS('REGISTRO DIARIO'!F:F,'REGISTRO DIARIO'!A:A,">="&DATE(2026,5,1),'REGISTRO DIARIO'!A:A,"<"&DATE(2026,6,1)) -> 0 | G6: =SUMIFS('REGISTRO DIARIO'!F:F,'REGISTRO DIARIO'!A:A,">="&DATE(2026,6,1),'REGISTRO DIARIO'!A:A,"<"&DATE(2026,7,1)) -> 0 | H6: =SUMIFS('REGISTRO DIARIO'!F:F,'REGISTRO DIARIO'!A:A,">="&DATE(2026,7,1),'REGISTRO DIARIO'!A:A,"<"&DATE(2026,8,1)) -> 38 | I6: =SUMIFS('REGISTRO DIARIO'!F:F,'REGISTRO DIARIO'!A:A,">="&DATE(2026,8,1),'REGISTRO DIARIO'!A:A,"<"&DATE(2026,9,1)) -> 0 | J6: =SUMIFS('REGISTRO DIARIO'!F:F,'REGISTRO DIARIO'!A:A,">="&DATE(2026,9,1),'REGISTRO DIARIO'!A:A,"<"&DATE(2026,10,1)) -> 0 | K6: =SUMIFS('REGISTRO DIARIO'!F:F,'REGISTRO DIARIO'!A:A,">="&DATE(2026,10,1),'REGISTRO DIARIO'!A:A,"<"&DATE(2026,11,1)) -> 0 | L6: =SUMIFS('REGISTRO DIARIO'!F:F,'REGISTRO DIARIO'!A:A,">="&DATE(2026,11,1),'REGISTRO DIARIO'!A:A,"<"&DATE(2026,12,1)) -> 0 | M6: =SUMIFS('REGISTRO DIARIO'!F:F,'REGISTRO DIARIO'!A:A,">="&DATE(2026,12,1),'REGISTRO DIARIO'!A:A,"<"&DATE(2027,1,1)) -> 0 | N6: Meta: ~35/mês
A7: Taxa de agendamento (%) | B7: =IFERROR(B6/B5,"") | C7: =IFERROR(C6/C5,"") | D7: =IFERROR(D6/D5,"") | E7: =IFERROR(E6/E5,"") | F7: =IFERROR(F6/F5,"") | G7: =IFERROR(G6/G5,"") | H7: =IFERROR(H6/H5,"") -> 0.30894309 | I7: =IFERROR(I6/I5,"") | ... M7: =IFERROR(M6/M5,"") | N7: Meta: ≥5%
A8: Taxa de fechamento (%) | B8: =IFERROR(B9/B6,"") | C8: =IFERROR(C9/C6,"") | D8: =IFERROR(D9/D6,"") | E8: =IFERROR(E9/E6,"") | F8: =IFERROR(F9/F6,"") | G8: =IFERROR(G9/G6,"") | H8: =IFERROR(H9/H6,"") -> 0.052631579 | I8: =IFERROR(I9/I6,"") | ... M8: =IFERROR(M9/M6,"") | N8: Meta: ≥11%
A9: Planos de ação fechados | B9: =SUMIFS('REGISTRO DIARIO'!G:G,'REGISTRO DIARIO'!A:A,">="&DATE(2026,1,1),'REGISTRO DIARIO'!A:A,"<"&DATE(2026,2,1)) -> 0 | C9: =SUMIFS('REGISTRO DIARIO'!G:G,'REGISTRO DIARIO'!A:A,">="&DATE(2026,2,1),'REGISTRO DIARIO'!A:A,"<"&DATE(2026,3,1)) -> 0 | D9: =SUMIFS('REGISTRO DIARIO'!G:G,'REGISTRO DIARIO'!A:A,">="&DATE(2026,3,1),'REGISTRO DIARIO'!A:A,"<"&DATE(2026,4,1)) -> 0 | E9: =SUMIFS('REGISTRO DIARIO'!G:G,'REGISTRO DIARIO'!A:A,">="&DATE(2026,4,1),'REGISTRO DIARIO'!A:A,"<"&DATE(2026,5,1)) -> 0 | F9: =SUMIFS('REGISTRO DIARIO'!G:G,'REGISTRO DIARIO'!A:A,">="&DATE(2026,5,1),'REGISTRO DIARIO'!A:A,"<"&DATE(2026,6,1)) -> 0 | G9: =SUMIFS('REGISTRO DIARIO'!G:G,'REGISTRO DIARIO'!A:A,">="&DATE(2026,6,1),'REGISTRO DIARIO'!A:A,"<"&DATE(2026,7,1)) -> 0 | H9: =SUMIFS('REGISTRO DIARIO'!G:G,'REGISTRO DIARIO'!A:A,">="&DATE(2026,7,1),'REGISTRO DIARIO'!A:A,"<"&DATE(2026,8,1)) -> 2 | I9: =SUMIFS('REGISTRO DIARIO'!G:G,'REGISTRO DIARIO'!A:A,">="&DATE(2026,8,1),'REGISTRO DIARIO'!A:A,"<"&DATE(2026,9,1)) -> 0 | J9: =SUMIFS('REGISTRO DIARIO'!G:G,'REGISTRO DIARIO'!A:A,">="&DATE(2026,9,1),'REGISTRO DIARIO'!A:A,"<"&DATE(2026,10,1)) -> 0 | K9: =SUMIFS('REGISTRO DIARIO'!G:G,'REGISTRO DIARIO'!A:A,">="&DATE(2026,10,1),'REGISTRO DIARIO'!A:A,"<"&DATE(2026,11,1)) -> 0 | L9: =SUMIFS('REGISTRO DIARIO'!G:G,'REGISTRO DIARIO'!A:A,">="&DATE(2026,11,1),'REGISTRO DIARIO'!A:A,"<"&DATE(2026,12,1)) -> 0 | M9: =SUMIFS('REGISTRO DIARIO'!G:G,'REGISTRO DIARIO'!A:A,">="&DATE(2026,12,1),'REGISTRO DIARIO'!A:A,"<"&DATE(2027,1,1)) -> 0 | N9: Meta: 4/mês
A10: Propostas de recorrente apresentadas | N10: Meta: = planos sem. 3
A11: Novos recorrentes assinados | N11: Meta: crescente
A12: Recorrentes acumulados | B12: =B11 | C12: =C11+B12 -> 0 | D12: =D11+C12 -> 0 | E12: =E11+D12 -> 0 | F12: =F11+E12 -> 0 | G12: =G11+F12 -> 0 | H12: =H11+G12 -> 0 | I12: =I11+H12 -> 0 | J12: =J11+I12 -> 0 | ... M12: =M11+L12 -> 0 | N12: Meta: 10 ao final do ano
A13: Leads convidados p/ comunidade | B13: =SUMIFS('REGISTRO DIARIO'!H:H,'REGISTRO DIARIO'!A:A,">="&DATE(2026,1,1),'REGISTRO DIARIO'!A:A,"<"&DATE(2026,2,1)) -> 0 | C13: =SUMIFS('REGISTRO DIARIO'!H:H,'REGISTRO DIARIO'!A:A,">="&DATE(2026,2,1),'REGISTRO DIARIO'!A:A,"<"&DATE(2026,3,1)) -> 0 | D13: =SUMIFS('REGISTRO DIARIO'!H:H,'REGISTRO DIARIO'!A:A,">="&DATE(2026,3,1),'REGISTRO DIARIO'!A:A,"<"&DATE(2026,4,1)) -> 0 | E13: =SUMIFS('REGISTRO DIARIO'!H:H,'REGISTRO DIARIO'!A:A,">="&DATE(2026,4,1),'REGISTRO DIARIO'!A:A,"<"&DATE(2026,5,1)) -> 0 | F13: =SUMIFS('REGISTRO DIARIO'!H:H,'REGISTRO DIARIO'!A:A,">="&DATE(2026,5,1),'REGISTRO DIARIO'!A:A,"<"&DATE(2026,6,1)) -> 0 | G13: =SUMIFS('REGISTRO DIARIO'!H:H,'REGISTRO DIARIO'!A:A,">="&DATE(2026,6,1),'REGISTRO DIARIO'!A:A,"<"&DATE(2026,7,1)) -> 0 | H13: =SUMIFS('REGISTRO DIARIO'!H:H,'REGISTRO DIARIO'!A:A,">="&DATE(2026,7,1),'REGISTRO DIARIO'!A:A,"<"&DATE(2026,8,1)) -> 12 | I13: =SUMIFS('REGISTRO DIARIO'!H:H,'REGISTRO DIARIO'!A:A,">="&DATE(2026,8,1),'REGISTRO DIARIO'!A:A,"<"&DATE(2026,9,1)) -> 0 | J13: =SUMIFS('REGISTRO DIARIO'!H:H,'REGISTRO DIARIO'!A:A,">="&DATE(2026,9,1),'REGISTRO DIARIO'!A:A,"<"&DATE(2026,10,1)) -> 0 | K13: =SUMIFS('REGISTRO DIARIO'!H:H,'REGISTRO DIARIO'!A:A,">="&DATE(2026,10,1),'REGISTRO DIARIO'!A:A,"<"&DATE(2026,11,1)) -> 0 | L13: =SUMIFS('REGISTRO DIARIO'!H:H,'REGISTRO DIARIO'!A:A,">="&DATE(2026,11,1),'REGISTRO DIARIO'!A:A,"<"&DATE(2026,12,1)) -> 0 | M13: =SUMIFS('REGISTRO DIARIO'!H:H,'REGISTRO DIARIO'!A:A,">="&DATE(2026,12,1),'REGISTRO DIARIO'!A:A,"<"&DATE(2027,1,1)) -> 0 | N13: Todos que não fecharam
A14: ── FINANCEIRO ──
A15: Ticket plano de ação (R$) — ajuste
A16: Ticket recorrente (R$) — ajuste
A17: Receita planos de ação (R$) | B17: =B9*B15 -> 0 | C17: =C9*C15 -> 0 | D17: =D9*D15 -> 0 | E17: =E9*E15 -> 0 | F17: =F9*F15 -> 0 | G17: =G9*G15 -> 0 | H17: =H9*H15 -> 0 | I17: =I9*I15 -> 0 | ... M17: =M9*M15 -> 0
A18: Receita recorrentes (R$) | B18: =B12*B16 -> 0 | C18: =C12*C16 -> 0 | D18: =D12*D16 -> 0 | E18: =E12*E16 -> 0 | F18: =F12*F16 -> 0 | G18: =G12*G16 -> 0 | H18: =H12*H16 -> 0 | I18: =I12*I16 -> 0 | ... M18: =M12*M16 -> 0
A19: RECEITA BRUTA TOTAL (R$) | B19: =B17+B18 -> 0 | C19: =C17+C18 -> 0 | D19: =D17+D18 -> 0 | E19: =E17+E18 -> 0 | F19: =F17+F18 -> 0 | G19: =G17+G18 -> 0 | H19: =H17+H18 -> 0 | I19: =I17+I18 -> 0 | ... M19: =M17+M18 -> 0
A20: Investimento em tráfego (R$) | N20: R$ 300-500/mês
A21: ROI do tráfego | B21: =IFERROR(B19/B20,"") | C21: =IFERROR(C19/C20,"") | D21: =IFERROR(D19/D20,"") | E21: =IFERROR(E19/E20,"") | F21: =IFERROR(F19/F20,"") | G21: =IFERROR(G19/G20,"") | H21: =IFERROR(H19/H20,"") | I21: =IFERROR(I19/I20,"") | ... M21: =IFERROR(M19/M20,"") | N21: Meta: ≥3x
A22: Custo por reunião (R$) | B22: =IFERROR(B20/B6,"") | C22: =IFERROR(C20/C6,"") | D22: =IFERROR(D20/D6,"") | E22: =IFERROR(E20/E6,"") | F22: =IFERROR(F20/F6,"") | G22: =IFERROR(G20/G6,"") | H22: =IFERROR(H20/H6,"") -> 0 | I22: =IFERROR(I20/I6,"") | ... M22: =IFERROR(M20/M6,"") | N22: acompanhar
A23: ── COMUNIDADE ──
A24: Posts na comunidade | N24: Meta: 8-12/mês
A25: Check-ins com leads quentes | N25: Meta: 5+/mês
A26: Conversões comunidade → fechamento | N26: Meta: ≥1/mês

Sheet PAINEL
A1: ACOMPANHAMENTO DE PROSPECÇÃO — Reunião Garantida
A2: Social Media: | B2: Digite seu nome aqui
A3: Mês de referência: | B3: 46204
A5: KPI | B5: PROSPECÇÕES (total do mês) | C5: REUNIÕES REALIZADAS (mês) | D5: FECHAMENTOS (mês)
A6: Valor | B6: =SEMANAL!G5 -> 123 | C6: =SEMANAL!G10 -> 38 | D6: =SEMANAL!G12 -> 2
A7: Meta | B7: 600 / mês | C7: ~35 / mês | D7: 4 / mês
A9: SEMÁFORO SEMANAL
A10: VERDE | B10: 150+ prospecções + 5+ reuniões agendadas + 1+ fechamento na semana
A11: AMARELO | B11: 100 a 149 prospecções ou nenhuma reunião agendada → revise o script de abertura
A12: VERMELHO | B12: menos de 100 prospecções ou nenhuma venda → pare e diagnostique
A14: STATUS ATUAL (Semana 1) | B14: =IF(SEMANAL!B5=0,"Preencha a aba SEMANAL",IF(SEMANAL!B5>=150,"No caminho! 150+ prospecções na Semana 1",IF(SEMANAL!B5>=100,"Atenção — entre 100 e 149. Revise sua rotina.","Ajuste urgente — menos de 100. Pare e diagnostique."))) -> Preencha a aba SEMANAL
A16: LEGENDA: | B16: Células em branco = preencha na aba SEMANAL | Taxas e totais são calculados automaticamente
